<?xml version="1.0"?>
<robot xmlns:xacro="http://www.ros.org/wiki/xacro" name="my_bot">


    <link name="base_footprint">
        
    </link>
    
    
    <link name="base_link">
        <inertial>
            <origin xyz="0.0 0.0 0.0" rpy="0.0 0.0 0.0"/>
            <mass value="2.0"/>
            <inertia ixx="0.32" ixy="0.0" ixz="0.0" iyy="0.32" iyz="0.0" izz="0.36"/>
        </inertial>
        <visual name="">
            <origin xyz="0.0 0.0 0.0" rpy="0.0 0.0 0.0"/>
            <geometry>
                <cylinder radius="0.6" length="0.06"/>
            </geometry>
            <material name="white">
                <color rgba="1.0 1.0 1.0 1.0"/>
                <texture filename=""/>
            </material>
        </visual>
        <collision>
            <origin xyz="0.0 0.0 0.0" rpy="0.0 0.0 0.0"/>
            <geometry>
                <cylinder radius="0.6" length="0.06"/>
            </geometry>
        </collision>
    </link>
    
    
   

     <joint name="base_link_joint" type="fixed">
        <origin xyz="0.0 0.0 0.19" rpy="0.0 0.0 0.0"/>
        <parent link="base_footprint"/>
        <child link="base_link"/>
        <axis xyz="0.0 0.0 0.0"/>
        <limit lower="0.0" upper="0.0" effort="0.0" velocity="0.0"/>
     </joint>


     <gazebo>
        <plugin name="differential_drive_controller" filename="libgazebo_ros_diff_drive.so">
            <!-- Plugin update rate in Hz -->
            <updateRate>20</updateRate>
            
            <!-- Name of left joint -->
            <leftJoint>left_wheel_joint</leftJoint>
            
            <!-- Name of right joint -->
            <rightJoint>right_wheel_joint</rightJoint>
            
            <!-- The distance from the center of one wheel to the other, in meters -->
            <wheelSeparation>1.14</wheelSeparation>
            
            <!-- Diameter of the wheels, in meters -->
            <wheelDiameter>0.4</wheelDiameter>
            
            <!-- Wheel acceleration, in rad/s^2 -->
            <wheelAcceleration>1.0</wheelAcceleration>
            
            <!-- Maximum torque which the wheels can produce, in Nm -->
            <wheelTorque>20</wheelTorque>
            
            <!-- Topic to receive geometry_msgs/Twist message commands -->
            <commandTopic>cmd_vel</commandTopic>
            
            <!-- Topic to publish nav_msgs/Odometry messages -->
            <odometryTopic>odom</odometryTopic>
            
            <!-- Odometry frame -->
            <odometryFrame>odom</odometryFrame>
            
            <!-- Robot frame to calculate odometry from -->
            <!-- Change this to base_link -->
            <robotBaseFrame>base_link</robotBaseFrame>
            
            <!-- Set to true to publish transforms for the wheel links -->
            <publishWheelTF>true</publishWheelTF>
            
            <!-- Set to true to publish transforms for the odometry -->
            <publishOdom>true</publishOdom>
            
            <!-- Set to true to publish sensor_msgs/JointState on /joint_states for the wheel joints -->
            <publishWheelJointState>true</publishWheelJointState>
            
            <!-- Set to true to swap right and left wheels -->
            <legacyMode>false</legacyMode>
        </plugin>
    </gazebo>  

      <link name="plate_link2">
        <inertial>
            <origin xyz="0.0 0.0 0.0" rpy="0.0 0.0 0.0"/>
            <mass value="2.0"/>
            <inertia ixx="0.32" ixy="0.0" ixz="0.0" iyy="0.32" iyz="0.0" izz="0.36"/>
        </inertial>
        <visual name="">
            <origin xyz="0.0 0.0 0.0" rpy="0.0 0.0 0.0"/>
            <geometry>
                <cylinder radius="0.6" length="0.06"/>
            </geometry>
            <material name="white">
                <color rgba="1.0 1.0 1.0 1.0"/>
                <texture filename=""/>
            </material>
        </visual>
        <collision>
            <origin xyz="0.0 0.0 0.0" rpy="0.0 0.0 0.0"/>
            <geometry>
                <cylinder radius="0.6" length="0.06"/>
            </geometry>
        </collision>
    </link>




    <joint name="plate_joint2" type="fixed">
        <origin xyz="0.0 -0.4 0.2" rpy="0.0 0.0 0.0"/>
        <parent link="stick_link"/>
        <child link="plate_link2"/>
        <axis xyz="0.0 0.0 0.0"/>
        <limit lower="0.0" upper="0.0" effort="0.0" velocity="0.0"/>
    </joint>

    


     <link name="laser_sensor_link">
        <inertial>
            <origin xyz="0.0 0.0 0.0" rpy="0.0 0.0 0.0"/>
            <mass value="0.2"/>
            <inertia ixx="0.00116667" ixy="0.0" ixz="0.0" iyy="0.00019167" iyz="0.0" izz="0.00019167"/>
        </inertial>
        <visual name="">
            <origin xyz="0.0 0.0 0.0" rpy="0.0 0.0 0.0"/>
            <geometry>
                <cylinder radius="0.1" length="0.1"/>
            </geometry>
            <material name="">
                <color rgba="1.0 0.0 0.0 1.0"/>
                <texture filename=""/>
            </material>
        </visual>
        <collision>
            <origin xyz="0.0 0.0 0.0" rpy="0.0 0.0 0.0"/>
            <geometry>
                <box size="0.0 0.0 0.0"/>
            </geometry>
        </collision>
     </link>



     <joint name="laser_sensor_joint" type="fixed">
        <origin xyz="0.5 0.0 0.08" rpy="0.0 0.0 0.0"/>
        <parent link="plate_link2"/>
        <child link="laser_sensor_link"/>
        <axis xyz="0.0 0.0 0.0"/>
        <limit lower="0.0" upper="0.0" effort="0.0" velocity="0.0"/>
     </joint>


     <!-- hokuyo -->
  <gazebo reference="laser_sensor_link">
    <sensor type="ray" name="head_hokuyo_sensor">
      <pose>0 0 0 0 0 0</pose>
      <visualize>true</visualize>
      <update_rate>40</update_rate>
      <ray>
        <scan>
          <horizontal>
            <samples>720</samples>
            <resolution>1</resolution>
            <min_angle>-1.570796</min_angle>
            <max_angle>1.570796</max_angle>
          </horizontal>
        </scan>
        <range>
          <min>0.10</min>
          <max>30.0</max>
          <resolution>0.01</resolution>
        </range>
        <noise>
          <type>gaussian</type>
          <!-- Noise parameters based on published spec for Hokuyo laser
               achieving "+-30mm" accuracy at range < 10m.  A mean of 0.0m and
               stddev of 0.01m will put 99.7% of samples within 0.03m of the true
               reading. -->
          <mean>0.0</mean>
          <stddev>0.01</stddev>
        </noise>
      </ray>
      <plugin name="gazebo_ros_head_hokuyo_controller" filename="libgazebo_ros_laser.so">
        <topicName>/scan</topicName>
        <frameName>laser_sensor_link</frameName>
      </plugin>
    </sensor>
  </gazebo>



     <link name="camera_strape">
        <inertial>
            <origin xyz="0.0 0.0 0.0" rpy="0.0 0.0 0.0"/>
            <mass value="0.1"/>
            <inertia ixx="0.0000083333" ixy="0.0" ixz="0.0" iyy="0.0004166667" iyz="0.0" izz="0.0004166667"/>
        </inertial>
        <visual name="">
            <origin xyz="0.0 0.0 0.0" rpy="0.0 0.0 0.0"/>
            <geometry>
                <box size="0.3 0.1 0.01"/>
            </geometry>
            <material name="">
                <color rgba="1.0 0.0 0.0 1.0"/>
                <texture filename=""/>
            </material>
        </visual>
        <collision>
            <origin xyz="0.0 0.0 0.0" rpy="0.0 0.0 0.0"/>
            <geometry>
                 <box size="0.3 0.1 0.01"/>
            </geometry>
        </collision>
     </link>



     <joint name="camera_joint" type="fixed">
        <origin xyz="-0.2 0.0 0.1" rpy="0.0 4.1 0.0"/>
        <parent link="plate_link2"/>
        <child link="camera_strape"/>
        <axis xyz="0.0 0.0 0.0"/>
        <limit lower="0.0" upper="0.0" effort="0.0" velocity="0.0"/>
     </joint>



     <link name="camera_strape2">
        <inertial>
            <origin xyz="0.0 0.0 0.0" rpy="0.0 0.0 0.0"/>
            <mass value="0.1"/>
            <inertia ixx="0.0000083333" ixy="0.0" ixz="0.0" iyy="0.0004166667" iyz="0.0" izz="0.0004166667"/>
        </inertial>
        <visual name="">
            <origin xyz="0.0 0.0 0.0" rpy="0.0 0.0 0.0"/>
            <geometry>
                <box size="0.3 0.1 0.01"/>
            </geometry>
            <material name="">
                <color rgba="1.0 0.0 0.0 1.0"/>
                <texture filename=""/>
            </material>
        </visual>
        <collision>
            <origin xyz="0.0 0.0 0.0" rpy="0.0 0.0 0.0"/>
            <geometry>
                 <box size="0.3 0.1 0.01"/>
            </geometry>
        </collision>
     </link>



     <joint name="camera_joint2" type="fixed">
        <origin xyz="0.23 0.0 -0.12" rpy="0.0 4.1 0.0"/>
        <parent link="camera_strape"/>
        <child link="camera_strape2"/>
        <axis xyz="0.0 0.0 0.0"/>
        <limit lower="0.0" upper="0.0" effort="0.0" velocity="0.0"/>
     </joint>




     <link name="OAK_link">
        <inertial>
            <origin xyz="0.0 0.0 0.0" rpy="0.0 0.0 0.0"/>
            <mass value="0.1"/>
            <inertia ixx="0.00010833" ixy="0.0" ixz="0.0" iyy="0.00002083" iyz="0.0" izz="0.00002083"/>
        </inertial>
        <visual name="">
            <origin xyz="0.0 0.0 0.0" rpy="0.0 0.0 0.0"/>
            <geometry>
                <box size="0.1 0.2 0.05"/>
            </geometry>
            <material name="">
                <color rgba="1.0 0.0 0.0 1.0"/>
                <texture filename=""/>
            </material>
        </visual>
        <collision>
            <origin xyz="0.0 0.0 0.0" rpy="0.0 0.0 0.0"/>
            <geometry>
                <box size="0.0 0.0 0.0"/>
            </geometry>
        </collision>
     </link>



     <joint name="OAK_joint" type="fixed">
        <origin xyz="-0.1 0.0 0.0" rpy="0.0 -0.33250 0.0"/>
        <parent link="camera_strape2"/>
        <child link="OAK_link"/>
        <axis xyz="0.0 0.0 0.0"/>
        <limit lower="0.0" upper="0.0" effort="0.0" velocity="0.0"/>
     </joint>



    <link name="stick_link">
        <inertial>
            <origin xyz="0.0 0.0 0.0" rpy="0.0 0.0 0.0"/>
            <mass value="0.3"/>
            <inertia ixx="0.0016" ixy="0.0" ixz="0.0" iyy="0.0016" iyz="0.0" izz="0.0012"/>
        </inertial>
        <visual name="">
            <origin xyz="0.0 0.0 0.0" rpy="0.0 0.0 0.0"/>
            <geometry>
                <cylinder radius="0.02" length="0.4"/>
            </geometry>
            <material name="">
                <color rgba="1.0 0.0 0.0 1.0"/>
                <texture filename=""/>
            </material>
        </visual>
        <collision>
            <origin xyz="0.0 0.0 0.0" rpy="0.0 0.0 0.0"/>
            <geometry>
                <box size="0.0 0.0 0.0"/>
            </geometry>
        </collision>
    </link>

    <joint name="stick_joint" type="fixed">
        <origin xyz="0.0 0.4 0.2" rpy="0.0 0.0 0.0"/>
        <parent link="base_link"/>
        <child link="stick_link"/>
        <axis xyz="0.0 0.0 0.0"/>
        <limit lower="0.0" upper="0.0" effort="0.0" velocity="0.0"/>
    </joint>


     <link name="stick_link2">
        <inertial>
            <origin xyz="0.0 0.0 0.0" rpy="0.0 0.0 0.0"/>
            <mass value="0.3"/>
            <inertia ixx="0.0016" ixy="0.0" ixz="0.0" iyy="0.0016" iyz="0.0" izz="0.0012"/>
        </inertial>
        <visual name="">
            <origin xyz="0.0 0.0 0.0" rpy="0.0 0.0 0.0"/>
            <geometry>
                <cylinder radius="0.02" length="0.4"/>
            </geometry>
            <material name="">
                <color rgba="1.0 0.0 0.0 1.0"/>
                <texture filename=""/>
            </material>
        </visual>
        <collision>
            <origin xyz="0.0 0.0 0.0" rpy="0.0 0.0 0.0"/>
            <geometry>
                <box size="0.0 0.0 0.0"/>
            </geometry>
        </collision>
    </link>

    <joint name="stick_joint2" type="fixed">
        <origin xyz="0.0 -0.4 0.2" rpy="0.0 0.0 0.0"/>
        <parent link="base_link"/>
        <child link="stick_link2"/>
        <axis xyz="0.0 0.0 0.0"/>
        <limit lower="0.0" upper="0.0" effort="0.0" velocity="0.0"/>
    </joint>



    <link name="stick_link3">
        <inertial>
            <origin xyz="0.0 0.0 0.0" rpy="0.0 0.0 0.0"/>
            <mass value="0.3"/>
           <inertia ixx="0.0016" ixy="0.0" ixz="0.0" iyy="0.0016" iyz="0.0" izz="0.0012"/>
        </inertial>
        <visual name="">
            <origin xyz="0.0 0.0 0.0" rpy="0.0 0.0 0.0"/>
            <geometry>
                <cylinder radius="0.02" length="0.4"/>
            </geometry>
            <material name="">
                <color rgba="1.0 0.0 0.0 1.0"/>
                <texture filename=""/>
            </material>
        </visual>
        <collision>
            <origin xyz="0.0 0.0 0.0" rpy="0.0 0.0 0.0"/>
            <geometry>
                <box size="0.0 0.0 0.0"/>
            </geometry>
        </collision>
    </link>

    <joint name="stick_joint3" type="fixed">
        <origin xyz="-0.4 0.0 0.2" rpy="0.0 0.0 0.0"/>
        <parent link="base_link"/>
        <child link="stick_link3"/>
        <axis xyz="0.0 0.0 0.0"/>
        <limit lower="0.0" upper="0.0" effort="0.0" velocity="0.0"/>
    </joint>






     <link name="right_wheel">
        <inertial>
            <origin xyz="0.0 0.0 0.0" rpy="0.0 0.0 0.0"/>
            <mass value="0.6"/>
            <inertia ixx="0.1" ixy="0.0" ixz="0.0" iyy="0.1" iyz="0.0" izz="0.3"/>
        </inertial>
        <visual name="">
            <origin xyz="0.0 0.0 0.0" rpy="0.0 0.0 0.0"/>
            <geometry>
                <cylinder radius="0.2" length="0.06"/>
            </geometry>
            <material name="red">
                <color rgba="1.0 0.0 0.0 1.0"/>
                <texture filename=""/>
            </material>
        </visual>
        <collision>
            <origin xyz="0.0 0.0 0.0" rpy="0.0 0.0 0.0"/>
            <geometry>
                 <cylinder radius="0.2" length="0.06"/>
            </geometry>
        </collision>
     </link>


     <joint name="right_wheel_joint" type="continuous">
        <origin xyz="0.0 -0.57 0.02" rpy="4.70 0.0 0.0"/>
        <parent link="base_link"/>
        <child link="right_wheel"/>
        <axis xyz="0.0 0.0 1.0"/>
        <limit lower="0.0" upper="0.0" effort="0.0" velocity="0.0"/>
     </joint>



     <link name="left_wheel">
        <inertial>
            <origin xyz="0.0 0.0 0.0" rpy="0.0 0.0 0.0"/>
            <mass value="0.6"/>
            <inertia ixx="0.1" ixy="0.0" ixz="0.0" iyy="0.1" iyz="0.0" izz="0.3"/>
        </inertial>
        <visual name="">
            <origin xyz="0.0 0.0 0.0" rpy="0.0 0.0 0.0"/>
            <geometry>
                <cylinder radius="0.2" length="0.06"/>
            </geometry>
            <material name="red">
                <color rgba="1.0 0.0 0.0 1.0"/>
                <texture filename=""/>
            </material>
        </visual>
        <collision>
            <origin xyz="0.0 0.0 0.0" rpy="0.0 0.0 0.0"/>
            <geometry>
               <cylinder radius="0.2" length="0.06"/>
            </geometry>
        </collision>
     </link>


     <joint name="left_wheel_joint" type="continuous">
        <origin xyz="0.0 0.57 0.02" rpy="4.70 0.0 0.0"/>
        <parent link="base_link"/>
        <child link="left_wheel"/>
        <axis xyz="0.0 0.0 1.0"/>
        <limit lower="0.0" upper="0.0" effort="0.0" velocity="0.0"/>
     </joint>




     <link name="front_caster_wheel">
        <inertial>
            <origin xyz="0.0 0.0 0.0" rpy="0.0 0.0 0.0"/>
            <mass value="0.2"/>
            <inertia ixx="0.000825" ixy="0.0" ixz="0.0" iyy="0.000825" iyz="0.001" izz="0.0"/>
        </inertial>
        <visual name="">
            <origin xyz="0.0 0.0 0.0" rpy="0.0 0.0 0.0"/>
            <geometry>
                <cylinder radius="0.08" length="0.03"/>
            </geometry>
            <material name="red">
                <color rgba="1.0 0.0 0.0 1.0"/>
                <texture filename=""/>
            </material>
        </visual>
        <collision>
            <origin xyz="0.0 0.0 0.0" rpy="0.0 0.0 0.0"/>
            <geometry>
               <cylinder radius="0.07" length="0.03"/>
            </geometry>
        </collision>
     </link>

     <joint name="front_caster_wheel_joint" type="continuous">
        <origin xyz="0.6 0.0 -0.1" rpy="-1.58 0.0 0.0"/>
        <parent link="base_link"/>
        <child link="front_caster_wheel"/>
        <axis xyz="0.0 0.0 1.0"/>
        <limit lower="0.0" upper="0.0" effort="0.0" velocity="0.0"/>
     </joint>



     <link name="back_caster_wheel">
        <inertial>
            <origin xyz="0.0 0.0 0.0" rpy="0.0 0.0 0.0"/>
            <mass value="0.2"/>
            <inertia ixx="0.000825" ixy="0.0" ixz="0.0" iyy="0.000825" iyz="0.001" izz="0.0"/>
        </inertial>
        <visual name="">
            <origin xyz="0.0 0.0 0.0" rpy="0.0 0.0 0.0"/>
            <geometry>
                <cylinder radius="0.08" length="0.03"/>
            </geometry>
            <material name="red">
                <color rgba="1.0 0.0 0.0 1.0"/>
                <texture filename=""/>
            </material>
        </visual>
        <collision>
            <origin xyz="0.0 0.0 0.0" rpy="0.0 0.0 0.0"/>
            <geometry>
               <cylinder radius="0.07" length="0.03"/>
            </geometry>
        </collision>
     </link>

     <joint name="back_caster_wheel_joint" type="continuous">
        <origin xyz="-0.6 0.0 -0.1" rpy="-1.58 0.0 0.0"/>
        <parent link="base_link"/>
        <child link="back_caster_wheel"/>
        <axis xyz="0.0 0.0 1.0"/>
        <limit lower="0.0" upper="0.0" effort="0.0" velocity="0.0"/>
     </joint>

    
    

</robot>